Workbook

Sheet Đọc trước
A1: Bảng ưu tiên tiếp cận trường – Bitsness (LMS, số hóa học liệu, khóa ngoại ngữ/khoa học/mô phỏng)
A2: Lập ngày 17/10/2026. Điểm hiện tại là SƠ BỘ, cần cập nhật sau khi bạn điền quan hệ (C8) và xác minh dữ liệu.
B4: MỤC ĐÍCH
B5: Xếp hạng 97 cơ sở đào tạo ở Hà Nội (51 cao đẳng, 30 đại học, 2 trung cấp, 14 TT GDNN-GDTX) để quyết định trường nào liên hệ trước.
B6: Mỗi trường được chấm 11 tiêu chí theo thang 1–5, nhân trọng số, quy về thang 100 và tự xếp vào Đợt 1/2/3/4.
B8: CÁCH DÙNG (4 BƯỚC)
B9: 1. Sheet 'Trọng số': xem lại trọng số 11 tiêu chí (ô vàng) và ngưỡng chia đợt. Tổng trọng số nên = 100.
B10: 2. Sheet 'Chấm điểm': điền cột C8 'Đường tiếp cận' (ô vàng đậm) cho từng trường. Mặc định = 1 (chưa quen ai). Đây là tiêu chí nặng nhất (12%), điền xong thứ hạng sẽ thay đổi đáng kể.
B11: 3. Trước khi gọi một trường, xác minh các dòng có cờ đỏ/cam ở cột 'Độ tin cậy dữ liệu', rồi sửa điểm C1–C11 cho đúng thực tế.
B12: 4. Sheet 'Pipeline': đã điền sẵn các trường Đợt 1 và Đợt 2. Cập nhật giai đoạn sau mỗi lần liên hệ; sheet 'Kế hoạch' tự đếm tiến độ phễu.
B13: Sau mỗi cuộc gặp, dùng sheet 'Câu hỏi khảo sát' để hỏi đúng các ý cần cho 11 tiêu chí, rồi quay lại sửa điểm.
B15: CHÚ GIẢI
B16: Ô nền vàng nhạt, chữ xanh dương: dữ liệu bạn nhập/sửa. Ô vàng đậm (cột C8): ưu tiên điền. Ô nền xám xanh: công thức, không gõ đè.
B17: Cột 'Độ tin cậy dữ liệu': đỏ = sai/không xác minh được; cam = chưa xác minh hoặc ước lượng; xanh = đã xác minh qua nguồn chính thức.
... B41: 5. 14 TT GDNN-GDTX cùng chủ quản là Sở GD&ĐT Hà Nội. Nên đề xuất ở cấp Sở (một nền tảng cho cả cụm) song song với pilot ở 1 trung tâm, thay vì đi lẻ 14 nơi.

Sheet Kế hoạch
A1: Kế hoạch tiếp cận: Hà Nội trước, ngoài Hà Nội sau
A2: Mốc thời gian tính từ tuần 19/10/2026. Số trường mỗi đợt và tiến độ phễu tự đếm.
A4: Đợt | B4: Số trường (tự đếm) | C4: Thời gian | D4: Mục tiêu đầu ra | E4: Trọng tâm & cách làm
A5: Đợt 1 | B5: =COUNTIF('Chấm điểm'!$W$5:$W$101,"Đợt 1*") -> 16 | C5: 02/11 – 20/12/2026 (7 tuần) | D5: Gặp ≥10 trường; khảo sát nhu cầu ≥6; gửi ≥3 đề xuất pilot để vào kế hoạch 2027 | E5: Ưu tiên trường công lập vừa sáp nhập (BGH mới, phải hợp nhất học liệu) và trường tư thục y–kỹ thuật quyết nhanh. Danh sách tự động hiện là 8 CĐ + 8 ĐH; nên chuyển 2–3 ĐH lớn, chu kỳ dài (HaUI, ĐH Dược, ĐH Xây dựng) sang Đợt 2 và đưa 2 trường trung cấp đang nâng cấp lên Đợt 1. Tận dụng 20/11 (Ngày Nhà giáo VN) để thăm hỏi, kết nối.
A6: Đợt 2 | B6: =COUNTIF('Chấm điểm'!$W$5:$W$101,"Đợt 2*") -> 36 | C6: 07/12/2026 – 24/01/2027 | D6: Liên hệ toàn bộ; gặp ≥12; chốt 1–2 pilot chạy học kỳ 2 | E6: Chạy song song phần cuối Đợt 1. Dùng phản hồi Đợt 1 chỉnh bộ chào hàng theo phân khúc. Gửi đề xuất cấp cụm cho Sở GD&ĐT về 14 TT GDNN-GDTX.
A7: Đợt 3 | B7: =COUNTIF('Chấm điểm'!$W$5:$W$101,"Đợt 3*") -> 41 | C7: 22/02 – 30/04/2027 | D7: Liên hệ theo nhóm qua hội thảo; chuyển pilot Đợt 1 thành hợp đồng | E7: Tổ chức 1 hội thảo chuyên đề (ví dụ 'Hợp nhất học liệu sau sáp nhập' hoặc 'Thực hành ảo cho trường nghề'), mời nhiều trường Đợt 3 cùng lúc, dùng case pilot Đợt 1 làm minh chứng.
A8: Đợt 4 – Ngoài HN | B8: =COUNTIF('Chấm điểm'!$W$5:$W$101,"Đợt 4*") -> 4 | C8: 05 – 07/2027 | D8: Mở rộng sang tỉnh lân cận với case study Hà Nội | E8: Giữ nguyên khung chấm điểm; thay C9 bằng khoảng cách/thời gian di chuyển từ Hà Nội. Ưu tiên tỉnh có cụm trường nghề (Bắc Ninh, Hưng Yên, Phú Thọ, Ninh Bình).
A10: LỊCH CÔNG VIỆC
A11: Giai đoạn | B11: Từ | C11: Đến | D11: Việc chính | E11: Đầu ra
A12: 0. Chuẩn bị | B12: 19/10/2026 | C12: 01/11/2026 | D12: • Xác minh 16 trường Đợt 1: website, gọi tổng đài/phòng Đào tạo, hỏi người quen. Sửa điểm C1, C5, C10. • Điền C8 (quan hệ) cho toàn bộ danh sách. • Bộ chào hàng theo 7 phân khúc (sheet Kịch bản): 1 trang giới thiệu + 1 đề xuất pilot mẫu. • Demo 3 mô-đun: 1 mô phỏng điện/ô tô, 1 mô phỏng điều dưỡng, 1 khóa tiếng Anh chuyên ngành. • Hồ sơ năng lực pháp nhân, bảng giá khung, gói pilot 1 học kỳ. • Kiểm tra học liệu có xuất SCORM/xAPI/LTI để chạy trên LMS sẵn có của trường. | E12: Danh sách Đợt 1 đã xác minh; bộ tài liệu; demo chạy được
A13: 1. Đợt 1 | B13: 02/11/2026 | C13: 20/12/2026 | D13: • Mỗi tuần liên hệ 3–4 trường, gặp 2. • Cuộc gặp đầu: hỏi theo sheet Câu hỏi khảo sát, không trình bày cả gói ngay. • Trong 5 ngày sau gặp: gửi tóm tắt nhu cầu + đề xuất pilot. • Cập nhật Pipeline sau mỗi lần liên hệ. | E13: ≥10 cuộc gặp, ≥3 đề xuất pilot
A14: 2. Đợt 2 | B14: 07/12/2026 | C14: 24/01/2027 | D14: • Tương tự Đợt 1, dùng bộ chào hàng đã chỉnh. • Gặp Sở GD&ĐT Hà Nội (phòng phụ trách GDNN-GDTX) về đề xuất cấp cụm cho 14 TT. | E14: ≥12 cuộc gặp, 1–2 pilot ký
A15: Tết Nguyên đán | B15: 25/01/2027 | C15: 21/02/2027 | D15: • Không mở liên hệ mới (Tết 06/02/2027). • Triển khai pilot, số hóa học liệu mẫu, viết case study. | E15: Case study đầu tiên
A16: 3. Đợt 3 + chuyển đổi | B16: 22/02/2027 | C16: 30/04/2027 | D16: • Hội thảo chuyên đề cho trường Đợt 3. • Đo kết quả pilot, đề xuất hợp đồng năm. | E16: Hợp đồng đầu tiên từ pilot
A17: 4. Ngoài Hà Nội | B17: 01/05/2027 | C17: 31/07/2027 | D17: • Chấm lại các trường tỉnh bằng cùng khung. • Tiếp cận qua hội thảo/đối tác địa phương. | E17: Danh sách tỉnh + 5–8 cuộc gặp
A19: PHỄU TIẾN ĐỘ (đếm từ sheet Pipeline)
A20: Giai đoạn | B20: Đã đạt (tự đếm) | C20: Mục tiêu hết Đợt 2 | D20: Tỷ lệ đạt | E20: Cách đếm
A21: 1. Trong danh sách | B21: =COUNTA(Pipeline!$A$6:$A$97) -> 52 | E21: Số trường có trong Pipeline
A22: 2. Đã liên hệ | B22: =COUNTIFS(Pipeline!$O$6:$O$97,">="&2,Pipeline!$O$6:$O$97,"<8") -> 0 | C22: 40 | D22: =IF(C22=0,"",B22/C22) -> 0 | E22: Số trường đã tới giai đoạn 2 trở lên (không tính Dừng/Mất)
A23: 3. Đã gặp | B23: =COUNTIFS(Pipeline!$O$6:$O$97,">="&3,Pipeline!$O$6:$O$97,"<8") -> 0 | C23: 22 | D23: =IF(C23=0,"",B23/C23) -> 0 | E23: Số trường đã tới giai đoạn 3 trở lên (không tính Dừng/Mất)
A24: 4. Đã khảo sát nhu cầu | B24: =COUNTIFS(Pipeline!$O$6:$O$97,">="&4,Pipeline!$O$6:$O$97,"<8") -> 0 | C24: 14 | D24: =IF(C24=0,"",B24/C24) -> 0 | E24: Số trường đã tới giai đoạn 4 trở lên (không tính Dừng/Mất)
A25: 5. Demo/Pilot | B25: =COUNTIFS(Pipeline!$O$6:$O$97,">="&5,Pipeline!$O$6:$O$97,"<8") -> 0 | C25: 5 | D25: =IF(C25=0,"",B25/C25) -> 0 | E25: Số trường đã tới giai đoạn 5 trở lên (không tính Dừng/Mất)
A26: 6. Đã gửi báo giá | B26: =COUNTIFS(Pipeline!$O$6:$O$97,">="&6,Pipeline!$O$6:$O$97,"<8") -> 0 | C26: 4 | D26: =IF(C26=0,"",B26/C26) -> 0 | E26: Số trường đã tới giai đoạn 6 trở lên (không tính Dừng/Mất)
A27: 7. Ký hợp đồng | B27: =COUNTIF(Pipeline!$O$6:$O$97,7) -> 0 | C27: 2 | D27: =IF(C27=0,"",B27/C27) -> 0 | E27: Số trường ở giai đoạn 7
A28: Mục tiêu phễu là giả định để theo dõi (bạn sửa ô vàng): khoảng 55% trường liên hệ được sẽ gặp, khoảng 60% số đã gặp đi tới khảo sát nhu cầu. Điều chỉnh sau 4 tuần đầu theo số liệu thật.

Sheet Trọng số
A1: Khung tiêu chí & trọng số
A2: Sửa ô vàng. Mọi điểm trong sheet 'Chấm điểm' và phân đợt cập nhật theo.
A4: Mã | B4: Tiêu chí | C4: Trọng số (%) | D4: Đo cái gì | E4: Điểm 1 | F4: Điểm 3 | G4: Điểm 5
A5: C1 | B5: Khoảng trống LMS | C5: 12 | D5: Trường càng thiếu LMS (đặc biệt LMS cho thực hành) thì nhu cầu càng lớn và ít bị nhà cung cấp cũ chiếm chỗ | E5: Đã có hệ sinh thái LMS tự phát triển/đồng bộ | F5: Có Moodle/e-learning lý thuyết | G5: Chưa có LMS hoặc chỉ dùng Google Classroom/Drive
A6: C2 | B6: Khớp mô phỏng | C6: 10 | D6: Số nhóm ngành khớp 4 mảng mô phỏng: điện–điện tử; cơ khí/ô tô/thiết bị; y tế–điều dưỡng; phòng thí nghiệm khoa học | E6: Không ngành nào khớp | F6: Khớp 1 nhóm ngành | G6: Khớp từ 3 nhóm, hoặc 1–2 nhóm 'rất khớp' và là thế mạnh trường
A7: C3 | B7: Nhu cầu ngoại ngữ | C7: 8 | D7: Áp lực chuẩn đầu ra ngoại ngữ, Đề án 2371 (tiếng Anh ngôn ngữ thứ hai), ngành cần ngoại ngữ (du lịch, điều dưỡng đi làm việc nước ngoài, hợp tác Hàn/Nhật/Đức) | E7: Ngành năng khiếu, ít cần ngoại ngữ | F7: Ngoại ngữ là môn chung/chuẩn đầu ra | G7: Ngoại ngữ là năng lực nghề cốt lõi hoặc có chương trình liên kết nước ngoài
A8: C4 | B8: Nhu cầu số hóa học liệu | C8: 10 | D8: Khối lượng giáo trình cần số hóa, ngành nặng thực hành, trường vừa gộp cần chuẩn hóa học liệu của nhiều trường cũ | E8: Đã có thư viện số/học liệu số đầy đủ | F8: Trường nghề thông thường, học liệu chủ yếu giấy/PDF | G8: Vừa sáp nhập/nâng cấp, phải hợp nhất học liệu nhiều đơn vị
A9: C5 | B9: Quy mô người học | C9: 8 | D9: Số HSSV và số ngành; quy mô càng lớn, giá trị hợp đồng và mức lan tỏa càng cao | E9: Trường nhỏ, chuyên biệt | F9: Quy mô trung bình / chưa rõ | G9: Trường lớn, nhiều ngành, nhiều cơ sở
A10: C6 | B10: Năng lực & tốc độ chi | C10: 10 | D10: Cơ chế tài chính và tốc độ ra quyết định: tư thục nhanh; công lập tự chủ khá; công lập phụ thuộc ngân sách chậm, qua dự toán/đấu thầu | E10: Phụ thuộc ngân sách, quy trình dài | F10: Công lập trực thuộc bộ/thành phố, có nguồn thu sự nghiệp | G10: Tư thục hoặc tự chủ tài chính, chủ trường quyết nhanh
A11: C7 | B11: Sự kiện kích hoạt | C11: 10 | D11: Có sự kiện buộc trường phải đầu tư ngay: mới sáp nhập, lãnh đạo mới, nâng cấp lên cao đẳng, kiểm định, đề án chuyển đổi số | E11: Không có sự kiện đặc biệt | F11: Có động lực chính sách chung (Đề án 2371, chuyển đổi số) | G11: Vừa sáp nhập/nâng cấp/đổi lãnh đạo trong 6 tháng qua
A12: C8 | B12: Đường tiếp cận | C12: 12 | D12: Bạn có người quen/giới thiệu tới người ra quyết định không. BẠN TỰ ĐIỀN (mặc định 1) | E12: Chưa có ai, tiếp cận lạnh | F12: Có người quen gián tiếp (cựu SV, đối tác, hội nhóm) | G12: Quen trực tiếp BGH/Trưởng phòng Đào tạo
A13: C9 | B13: Khoảng cách | C13: 6 | D13: Vùng theo khoảng cách từ Hà Đông; ảnh hưởng chi phí gặp trực tiếp và hỗ trợ triển khai | E13: Ngoài Hà Nội | F13: Vùng 3 (11–15 km) | G13: Vùng 1 (≤5 km)
A14: C10 | B14: Năng lực triển khai phía trường | C14: 7 | D14: Trường có đủ hạ tầng, nhân sự CNTT và thói quen số để dùng được sản phẩm (đối trọng của C1: trường quá sơ khai thì triển khai rủi ro) | E14: Sơ khai: dữ liệu rời rạc trên bảng tính | F14: Trung bình: đã có cổng tra cứu/tuyển sinh online | G14: Đã số hóa quản lý bài bản
A15: C11 | B15: Giá trị tham chiếu | C15: 7 | D15: Thắng trường này có giúp bán cho trường khác không (trường đầu tàu, cùng hệ thống với nhiều trường, thương hiệu lớn) | E15: Trường lẻ, ít ảnh hưởng | F15: Trường trung bình trong mạng lưới | G15: Đầu tàu ngành/thuộc hệ thống nhiều trường cùng chủ quản
B16: Tổng trọng số | C16: =SUM(C5:C15) -> 100 | D16: =IF(C16=100,"OK","Lưu ý: tổng khác 100, điểm vẫn quy về thang 100 nhưng nên giữ 100 cho dễ đọc") -> OK
B17: Nhóm: Nhu cầu (C1–C4) = 40%; Khả năng mua (C5–C7) = 28%; Tiếp cận (C8–C9) = 18%; Khả thi & lan tỏa (C10–C11) = 14%
B19: Ngưỡng Đợt 1 (điểm ≥) | C19: 70 | D19: Chọn 70 để Đợt 1 có khoảng 16 trường, vừa sức tiếp cận trong 7 tuần (xem sheet Kế hoạch). Dưới ngưỡng Đợt 2 là Đợt 3. Trường ngoài Hà Nội luôn vào Đợt 4.
B20: Ngưỡng Đợt 2 (điểm ≥) | C20: 65

Sheet Chấm điểm
A1: Chấm điểm & xếp hạng
A2: Ô vàng là dữ liệu nhập. C8 (cột R) mặc định 1, hãy điền. C9 tự tính từ cột Vùng. Dùng bộ lọc ở hàng tiêu đề để sắp xếp/lọc theo Đợt, Loại hình.
J3: Trọng số → | K3: ='Trọng số'!C5 -> 12 | L3: ='Trọng số'!C6 -> 10 | M3: ='Trọng số'!C7 -> 8 | N3: ='Trọng số'!C8 -> 10 | O3: ='Trọng số'!C9 -> 8 | P3: ='Trọng số'!C10 -> 10 | Q3: ='Trọng số'!C11 -> 10 | R3: ='Trọng số'!C12 -> 12 | S3: ='Trọng số'!C13 -> 6 | T3: ='Trọng số'!C14 -> 7 | U3: ='Trọng số'!C15 -> 7
A4: Hạng | B4: Trường | C4: Loại hình | D4: Chủ quản | E4: Vùng | F4: Km từ Hà Đông (file gốc) | G4: Ngành chính | H4: Hiện trạng LMS (file gốc) | I4: Số hóa quản lý (file gốc) | J4: Sự kiện kích hoạt | K4: C1 Khoảng trống LMS | L4: C2 Khớp mô phỏng | M4: C3 Nhu cầu ngoại ngữ | N4: C4 Nhu cầu số hóa học liệu | O4: C5 Quy mô người học | P4: C6 Năng lực & tốc độ chi | Q4: C7 Sự kiện kích hoạt | R4: C8 Đường tiếp cận | S4: C9 Khoảng cách | T4: C10 Năng lực triển khai phía trường | U4: C11 Giá trị tham chiếu | V4: Tổng điểm (/100) | W4: Đợt đề xuất | X4: Gói chào mở cửa (tự động) | Y4: Độ tin cậy dữ liệu | Z4: Căn cứ chấm sơ bộ (từng tiêu chí) | AA4: Ghi chú | AB4: Website | AC4: Nguồn dòng
A5: =RANK(V5,$V$5:$V$101) -> 1 | B5: Trường ĐH Phenikaa | C5: Đại học | D5: Tư thục | E5: 1 | G5: Kỹ thuật, ô tô, điện tử, y dược, điều dưỡng | H5: Cần khảo sát (chưa rõ, giả định có LMS/Moodle cơ bản) | I5: Cần khảo sát | J5: Đề án 2371: chuẩn đầu ra tiếng Anh | K5: 3 | L5: 5 | M5: 5 | N5: 4 | O5: 5 | P5: 5 | Q5: 3 | R5: 1 | S5: =IF(E5="Ngoài HN",1,IF(E5="","",6-VALUE(E5))) -> 5 | T5: 5 | U5: 4 | V5: =ROUND(SUMPRODUCT(K5:U5,$K$3:$U$3)/(5*SUM($K$3:$U$3))*100,1) -> 78.2 | W5: =IF(E5="Ngoài HN","Đợt 4 – Ngoài HN",IF(V5>='Trọng số'!$C$19,"Đợt 1",IF(V5>='Trọng số'!$C$20,"Đợt 2","Đợt 3"))) -> Đợt 1 | X5: =IF(K5>=4,"LMS + số hóa học liệu",IF(K5=3,"Nâng cấp/thay LMS + số hóa học liệu","Số hóa học liệu, chạy trên LMS sẵn có"))&IF(L5>=4," + mô phỏng","")&IF(M5>=4," + ngoại ngữ","") -> Nâng cấp/thay LMS + số hóa học liệu + mô phỏng + ngoại ngữ | Y5: Ước lượng – LMS/quy mô cần khảo sát | Z5: C1=3: chưa rõ, giả định có LMS/Moodle cơ bản | C2=5: khớp: điện–điện tử, cơ khí/ô tô/thiết bị, y tế, lab khoa học | C3=5: Đề án 2371 + chuẩn đầu ra tiếng Anh ĐH | C4=4: khối lượng giáo trình lớn | C5=5: rất lớn | C6=5: Tư thục | C7=3: Đề án 2371: chuẩn đầu ra tiếng Anh | C8=1: chưa có quan hệ (tự cập nhật) | C9=5: Vùng 1 (ước lượng) | C10=5: hạ tầng CNTT mạnh | C11=4: uy tín trong khối ngành | AC5: Bổ sung
A6: =RANK(V6,$V$5:$V$101) -> 2 | B6: CĐ Y tế Hà Nội (đã hợp nhất CĐ Y tế Hà Đông) | C6: Cao đẳng | D6: Công lập – TP Hà Nội | E6: 1 | F6: 1.5 | G6: Kỹ thuật Xét nghiệm y học, Điều dưỡng, Dược, Thiết bị y tế cơ bản | H6: Chưa có LMS thực hành. Đang duy trì cổng thông tin đào tạo trên cdythadong.edu.vn. | I6: Cơ bản. Đã có tra cứu điểm thi, quản lý hồ sơ sinh viên nội bộ qua website. | J6: Hợp nhất CĐ Y tế Hà Đông + CĐ Y tế Hà Nội (QĐ 2026); BGH mới bổ nhiệm 6/10/2026 | K6: 5 | L6: 5 | M6: 4 | N6: 5 | O6: 4 | P6: 3 | Q6: 5 | R6: 1 | S6: =IF(E6="Ngoài HN",1,IF(E6="","",6-VALUE(E6))) -> 5 | T6: 2 | U6: 4 | V6: =ROUND(SUMPRODUCT(K6:U6,$K$3:$U$3)/(5*SUM($K$3:$U$3))*100,1) -> 77.6 | W6: =IF(E6="Ngoài HN","Đợt 4 – Ngoài HN",IF(V6>='Trọng số'!$C$19,"Đợt 1",IF(V6>='Trọng số'!$C$20,"Đợt 2","Đợt 3"))) -> Đợt 1 | X6: =IF(K6>=4,"LMS + số hóa học liệu",IF(K6=3,"Nâng cấp/thay LMS + số hóa học liệu","Số hóa học liệu, chạy trên LMS sẵn có"))&IF(L6>=4," + mô phỏng","")&IF(M6>=4," + ngoại ngữ","") -> LMS + số hóa học liệu + mô phỏng + ngoại ngữ | Y6: Đã xác minh sáp nhập; hiện trạng LMS là của CĐ Y tế Hà Đông cũ | Z6: C1=5: chưa có LMS (theo file) | C2=5: khớp: cơ khí/ô tô/thiết bị, y tế, lab khoa học | C3=4: điều dưỡng/y tế: nhu cầu tiếng Nhật/Đức/Anh để làm việc nước ngoài | C4=5: vừa gộp trường, phải hợp nhất học liệu | C5=4: lớn, nhiều ngành | C6=3: Công lập – TP Hà Nội | C7=5: Hợp nhất CĐ Y tế Hà Đông + CĐ Y tế Hà Nội (QĐ 2026); BGH mới bổ nhiệm 6/10/2026 | C8=1: chưa có quan hệ (tự cập nhật) | C9=5: Vùng 1 | C10=2: số hóa quản lý cơ bản | C11=4: thuộc hệ thống trường của TP/bộ, dễ nhân rộng | AA6: Hiệu trưởng: Phạm Văn Tân (TB 750-TB/TU) | AB6: cdythadong.edu.vn | AC6: File gốc #1
A7: =RANK(V7,$V$5:$V$101) -> 3 | B7: CĐ nghề Việt Nam – Hàn Quốc TP Hà Nội | C7: Cao đẳng | D7: Công lập – TP Hà Nội | E7: 3 | G7: Cơ khí, điện – điện tử, ô tô, CNTT (hợp tác Hàn Quốc) | H7: Cần khảo sát | I7: Cần khảo sát | J7: Nhận sáp nhập 2 trường trung cấp (KH 292/KH-UBND); BGH mới 6/10/2026 | K7: 4 | L7: 4 | M7: 5 | N7: 5 | O7: 4 | P7: 3 | Q7: 5 | R7: 1 | S7: =IF(E7="Ngoài HN",1,IF(E7="","",6-VALUE(E7))) -> 3 | T7: 3 | U7: 4 | V7: =ROUND(SUMPRODUCT(K7:U7,$K$3:$U$3)/(5*SUM($K$3:$U$3))*100,1) -> 73.8 | W7: =IF(E7="Ngoài HN","Đợt 4 – Ngoài HN",IF(V7>='Trọng số'!$C$19,"Đợt 1",IF(V7>='Trọng số'!$C$20,"Đợt 2","Đợt 3"))) -> Đợt 1 | X7: =IF(K7>=4,"LMS + số hóa học liệu",IF(K7=3,"Nâng cấp/thay LMS + số hóa học liệu","Số hóa học liệu, chạy trên LMS sẵn có"))&IF(L7>=4," + mô phỏng","")&IF(M7>=4," + ngoại ngữ","") -> LMS + số hóa học liệu + mô phỏng + ngoại ngữ | Y7: Đã xác minh sáp nhập; vị trí/LMS cần khảo sát | Z7: C1=4: chưa rõ, giả định LMS rời rạc sau sáp nhập | C2=4: khớp: điện–điện tử, cơ khí/ô tô | C3=5: tiếng Hàn là lợi thế cốt lõi | C4=5: vừa nhận 2 trường trung cấp, phải hợp nhất học liệu | C5=4: lớn sau sáp nhập | C6=3: Công lập – TP Hà Nội | C7=5: Nhận sáp nhập 2 trường trung cấp (KH 292/KH-UBND); BGH mới 6/10/2026 (TC nghề Cơ khí I HN + TC KT-KT Bắc Thăng Long) | C8=1: chưa có quan hệ (tự cập nhật) | C9=3: Vùng 3 (ước lượng) | C10=3: chưa rõ | C11=4: thuộc hệ thống trường của TP | AA7: Hiệu trưởng: Nguyễn Công Truyền (TB 750-TB/TU) | AC7: Bổ sung
A8: =RANK(V8,$V$5:$V$101) -> 4 | B8: CĐ Kỹ thuật - Công nghệ Bách Khoa (CTECH) | C8: Cao đẳng | D8: Tư thục | E8: 3 | F8: 13 | G8: Thiết kế vi mạch, Điện tử - Viễn thông, Cơ điện tử, Ô tô | H8: Chưa có LMS thực hành. Cổng thông tin chính tại ctech.edu.vn, tuyển sinh tại tuyensinh.ctech.edu.vn. | I8: Đang nâng cấp. Trường tư thục quy mô lớn đang đầu tư mạnh vào cơ sở vật chất mới. | J8: Đang đầu tư mạnh cơ sở vật chất mới | K8: 5 | L8: 5 | M8: 3 | N8: 4 | O8: 4 | P8: 5 | Q8: 4 | R8: 1 | S8: =IF(E8="Ngoài HN",1,IF(E8="","",6-VALUE(E8))) -> 3 | T8: 3 | U8: 3 | V8: =ROUND(SUMPRODUCT(K8:U8,$K$3:$U$3)/(5*SUM($K$3:$U$3))*100,1) -> 73.6 | W8: =IF(E8="Ngoài HN","Đợt 4 – Ngoài HN",IF(V8>='Trọng số'!$C$19,"Đợt 1",IF(V8>='Trọng số'!$C$20,"Đợt 2","Đợt 3"))) -> Đợt 1 | X8: =IF(K8>=4,"LMS + số hóa học liệu",IF(K8=3,"Nâng cấp/thay LMS + số hóa học liệu","Số hóa học liệu, chạy trên LMS sẵn có"))&IF(L8>=4," + mô phỏng","")&IF(M8>=4," + ngoại ngữ","") -> LMS + số hóa học liệu + mô phỏng | Y8: Chưa xác minh (file gốc) | Z8: C1=5: chưa có LMS (theo file) | C2=5: khớp: điện–điện tử, cơ khí/ô tô/thiết bị | C3=3: ngoại ngữ là chuẩn đầu ra chung | C4=4: trường nghề nặng thực hành, học liệu chủ yếu giấy/PDF | C5=4: lớn, nhiều ngành | C6=5: Tư thục | C7=4: Đang đầu tư mạnh cơ sở vật chất mới | C8=1: chưa có quan hệ (tự cập nhật) | C9=3: Vùng 3 | C10=3: đang nâng cấp | C11=3: trường trong mạng lưới | AB8: ctech.edu.vn | AC8: File gốc #34
A9: =RANK(V9,$V$5:$V$101) -> 5 | B9: CĐ Thương mại và Du lịch Hà Nội (đã nhận CĐ Cộng đồng HN) | C9: Cao đẳng | D9: Công lập – TP Hà Nội | E9: 3 | F9: 12.5 | G9: Kỹ thuật chế biến món ăn, Thương mại điện tử, Quản trị mạng | H9: Có cổng học tập số. Chia sẻ kho bài giảng điện tử và kiểm tra trắc nghiệm online. | I9: Khá. Có phân hệ quản trị đào tạo theo tín chỉ và cổng tiếp nhận sinh viên. | J9: Nhận sáp nhập CĐ Cộng đồng HN + TC Nấu ăn-NVDL&TT HN; BGH mới 6/10/2026 | K9: 3 | L9: 4 | M9: 5 | N9: 5 | O9: 4 | P9: 3 | Q9: 5 | R9: 1 | S9: =IF(E9="Ngoài HN",1,IF(E9="","",6-VALUE(E9))) -> 3 | T9: 4 | U9: 4 | V9: =ROUND(SUMPRODUCT(K9:U9,$K$3:$U$3)/(5*SUM($K$3:$U$3))*100,1) -> 72.8 | W9: =IF(E9="Ngoài HN","Đợt 4 – Ngoài HN",IF(V9>='Trọng số'!$C$19,"Đợt 1",IF(V9>='Trọng số'!$C$20,"Đợt 2","Đợt 3"))) -> Đợt 1 | X9: =IF(K9>=4,"LMS + số hóa học liệu",IF(K9=3,"Nâng cấp/thay LMS + số hóa học liệu","Số hóa học liệu, chạy trên LMS sẵn có"))&IF(L9>=4," + mô phỏng","")&IF(M9>=4," + ngoại ngữ","") -> Nâng cấp/thay LMS + số hóa học liệu + mô phỏng + ngoại ngữ | Y9: Đã xác minh sáp nhập; gộp dòng #15 (CĐ Cộng đồng HN) vào đây | Z9: C1=3: có e-learning lý thuyết | C2=4: khớp: điện–điện tử, lab khoa học | C3=5: ngành du lịch/thương mại/liên kết Hàn: ngoại ngữ là năng lực nghề | C4=5: vừa gộp trường, phải hợp nhất học liệu | C5=4: lớn, nhiều ngành | C6=3: Công lập – TP Hà Nội | C7=5: Nhận sáp nhập CĐ Cộng đồng HN + TC Nấu ăn-NVDL&TT HN; BGH mới 6/10/2026 | C8=1: chưa có quan hệ (tự cập nhật) | C9=3: Vùng 3 | C10=4: số hóa quản lý khá | C11=4: thuộc hệ thống trường của TP/bộ, dễ nhân rộng | AA9: Hiệu trưởng: Trịnh Thị Thu Hà (TB 750-TB/TU) | AB9: hcat.edu.vn | AC9: File gốc #33 + #15
A10: =RANK(V10,$V$5:$V$101) -> 5 | B10: Trường ĐH Công nghiệp Hà Nội (HaUI) | C10: Đại học | D10: Công lập – tự chủ | E10: 3 | G10: Cơ khí, điện, điện tử, ô tô, ngoại ngữ | H10: Cần khảo sát (nhiều khả năng đã có LMS (giả định)) | I10: Cần khảo sát | J10: Đề án 2371 | K10: 2 | L10: 5 | M10: 5 | N10: 4 | O10: 5 | P10: 4 | Q10: 3 | R10: 1 | S10: =IF(E10="Ngoài HN",1,IF(E10="","",6-VALUE(E10))) -> 3 | T10: 5 | U10: 5 | V10: =ROUND(SUMPRODUCT(K10:U10,$K$3:$U$3)/(5*SUM($K$3:$U$3))*100,1) -> 72.8 | W10: =IF(E10="Ngoài HN","Đợt 4 – Ngoài HN",IF(V10>='Trọng số'!$C$19,"Đợt 1",IF(V10>='Trọng số'!$C$20,"Đợt 2","Đợt 3"))) -> Đợt 1 | X10: =IF(K10>=4,"LMS + số hóa học liệu",IF(K10=3,"Nâng cấp/thay LMS + số hóa học liệu","Số hóa học liệu, chạy trên LMS sẵn có"))&IF(L10>=4," + mô phỏng","")&IF(M10>=4," + ngoại ngữ","") -> Số hóa học liệu, chạy trên LMS sẵn có + mô phỏng + ngoại ngữ | Y10: Ước lượng – LMS/quy mô cần khảo sát | Z10: C1=2: nhiều khả năng đã có LMS (giả định) | C2=5: khớp: điện–điện tử, cơ khí/ô tô/thiết bị | C3=5: Đề án 2371 + chuẩn đầu ra tiếng Anh ĐH | C4=4: khối lượng giáo trình lớn | C5=5: rất lớn | C6=4: Công lập – tự chủ | C7=3: Đề án 2371 | C8=1: chưa có quan hệ (tự cập nhật) | C9=3: Vùng 3 (ước lượng) | C10=5: hạ tầng CNTT mạnh | C11=5: thương hiệu đầu ngành | AA10: Quy mô rất lớn; nhiều khả năng đã có hệ thống riêng | AC10: Bổ sung
A11: =RANK(V11,$V$5:$V$101) -> 7 | B11: CĐ nghề Công nghiệp Hà Nội (HNIVC) | C11: Cao đẳng | D11: Công lập – TP Hà Nội | E11: 2 | F11: 7.5 | G11: Điện - Điện tử, Cơ điện tử, Tự động hóa, Ô tô, Cơ khí CNC | H11: Đã có LMS chuẩn: elearning.hnivc.edu.vn. Quản lý sinh viên tại sinhvien.hnivc.edu.vn. | I11: Đã số hóa bài bản. Tách biệt rõ ràng giữa quản lý đào tạo, hồ sơ sinh viên và cổng LMS. | J11: Nhận sáp nhập TC Kỹ thuật Tin học HN + TC KT-KT&CN HN; BGH mới 6/10/2026 | K11: 2 | L11: 5 | M11: 3 | N11: 5 | O11: 4 | P11: 3 | Q11: 5 | R11: 1 | S11: =IF(E11="Ngoài HN",1,IF(E11="","",6-VALUE(E11))) -> 4 | T11: 5 | U11: 4 | V11: =ROUND(SUMPRODUCT(K11:U11,$K$3:$U$3)/(5*SUM($K$3:$U$3))*100,1) -> 71.8 | W11: =IF(E11="Ngoài HN","Đợt 4 – Ngoài HN",IF(V11>='Trọng số'!$C$19,"Đợt 1",IF(V11>='Trọng số'!$C$20,"Đợt 2","Đợt 3"))) -> Đợt 1 | X11: =IF(K11>=4,"LMS + số hóa học liệu",IF(K11=3,"Nâng cấp/thay LMS + số hóa học liệu","Số hóa học liệu, chạy trên LMS sẵn có"))&IF(L11>=4," + mô phỏng","")&IF(M11>=4," + ngoại ngữ","") -> Số hóa học liệu, chạy trên LMS sẵn có + mô phỏng | Y11: Đã xác minh sáp nhập | Z11: C1=2: đã có LMS đầy đủ | C2=5: khớp: điện–điện tử, cơ khí/ô tô/thiết bị, lab khoa học | C3=3: ngoại ngữ là chuẩn đầu ra chung | C4=5: vừa gộp trường, phải hợp nhất học liệu | C5=4: lớn, nhiều ngành | C6=3: Công lập – TP Hà Nội | C7=5: Nhận sáp nhập TC Kỹ thuật Tin học HN + TC KT-KT&CN HN; BGH mới 6/10/2026 | C8=1: chưa có quan hệ (tự cập nhật) | C9=4: Vùng 2 | C10=5: đã số hóa quản lý tốt | C11=4: thuộc hệ thống trường của TP/bộ, dễ nhân rộng | AA11: Hiệu trưởng: Phạm Thị Hường (TB 750-TB/TU) | AB11: hnivc.edu.vn | AC11: File gốc #14
A12: =RANK(V12,$V$5:$V$101) -> 8 | B12: Trường ĐH Xây dựng Hà Nội | C12: Đại học | D12: Công lập – tự chủ | E12: 2 | G12: Xây dựng, cơ khí, môi trường, BIM | H12: Cần khảo sát (chưa rõ, giả định có LMS/Moodle cơ bản) | I12: Cần khảo sát | J12: Đề án 2371 | K12: 3 | L12: 4 | M12: 4 | N12: 4 | O12: 5 | P12: 4 | Q12: 3 | R12: 1 | S12: =IF(E12="Ngoài HN",1,IF(E12="","",6-VALUE(E12))) -> 4 | T12: 5 | U12: 4 | V12: =ROUND(SUMPRODUCT(K12:U12,$K$3:$U$3)/(5*SUM($K$3:$U$3))*100,1) -> 71.4 | W12: =IF(E12="Ngoài HN","Đợt 4 – Ngoài HN",IF(V12>='Trọng số'!$C$19,"Đợt 1",IF(V12>='Trọng số'!$C$20,"Đợt 2","Đợt 3"))) -> Đợt 1 | X12: =IF(K12>=4,"LMS + số hóa học liệu",IF(K12=3,"Nâng cấp/thay LMS + số hóa học liệu","Số hóa học liệu, chạy trên LMS sẵn có"))&IF(L12>=4," + mô phỏng","")&IF(M12>=4," + ngoại ngữ","") -> Nâng cấp/thay LMS + số hóa học liệu + mô phỏng + ngoại ngữ | Y12: Ước lượng – LMS/quy mô cần khảo sát | Z12: C1=3: chưa rõ, giả định có LMS/Moodle cơ bản | C2=4: khớp: cơ khí/ô tô/thiết bị, lab khoa học | C3=4: Đề án 2371 + chuẩn đầu ra tiếng Anh ĐH | C4=4: khối lượng giáo trình lớn | C5=5: rất lớn | C6=4: Công lập – tự chủ | C7=3: Đề án 2371 | C8=1: chưa có quan hệ (tự cập nhật) | C9=4: Vùng 2 (ước lượng) | C10=5: hạ tầng CNTT mạnh | C11=4: uy tín trong khối ngành | AC12: Bổ sung
A13: =RANK(V13,$V$5:$V$101) -> 9 | B13: CĐ Điện tử - Điện lạnh Hà Nội (CER) | C13: Cao đẳng | D13: Công lập – TP Hà Nội | E13: 2 | F13: 10.2 | G13: Điện tử công nghiệp, Kỹ thuật máy lạnh (VRV/Chiller), Xe điện | H13: Có E-learning từ xa: Tích hợp trên dtdl.edu.vn/gioi-thieu/ (hợp tác triển khai cùng AUM). | I13: Khá. Đã số hóa cổng sinh viên và lịch giảng dạy trực tuyến. | J13: Nhận sáp nhập TC nghề số 1 HN + TC Xây dựng HN; BGH mới 6/10/2026 | K13: 3 | L13: 4 | M13: 3 | N13: 5 | O13: 4 | P13: 3 | Q13: 5 | R13: 1 | S13: =IF(E13="Ngoài HN",1,IF(E13="","",6-VALUE(E13))) -> 4 | T13: 4 | U13: 4 | V13: =ROUND(SUMPRODUCT(K13:U13,$K$3:$U$3)/(5*SUM($K$3:$U$3))*100,1) -> 70.8 | W13: =IF(E13="Ngoài HN","Đợt 4 – Ngoài HN",IF(V13>='Trọng số'!$C$19,"Đợt 1",IF(V13>='Trọng số'!$C$20,"Đợt 2","Đợt 3"))) -> Đợt 1 | X13: =IF(K13>=4,"LMS + số hóa học liệu",IF(K13=3,"Nâng cấp/thay LMS + số hóa học liệu","Số hóa học liệu, chạy trên LMS sẵn có"))&IF(L13>=4," + mô phỏng","")&IF(M13>=4," + ngoại ngữ","") -> Nâng cấp/thay LMS + số hóa học liệu + mô phỏng | Y13: Đã xác minh sáp nhập | Z13: C1=3: có e-learning lý thuyết | C2=4: khớp: điện–điện tử | C3=3: ngoại ngữ là chuẩn đầu ra chung | C4=5: vừa gộp trường, phải hợp nhất học liệu | C5=4: lớn, nhiều ngành | C6=3: Công lập – TP Hà Nội | C7=5: Nhận sáp nhập TC nghề số 1 HN + TC Xây dựng HN; BGH mới 6/10/2026 | C8=1: chưa có quan hệ (tự cập nhật) | C9=4: Vùng 2 | C10=4: số hóa quản lý khá | C11=4: thuộc hệ thống trường của TP/bộ, dễ nhân rộng | AA13: Hiệu trưởng: Trần Xuân Ngọc (TB 750-TB/TU) | AB13: dtdl.edu.vn | AC13: File gốc #24
A14: =RANK(V14,$V$5:$V$101) -> 10 | B14: Trường ĐH Kinh doanh và Công nghệ Hà Nội (HUBT) | C14: Đại học | D14: Tư thục | E14: 2 | G14: Y, dược, kỹ thuật, kinh tế | H14: Cần khảo sát (chưa rõ, giả định có LMS/Moodle cơ bản) | I14: Cần khảo sát | J14: Đề án 2371 | K14: 3 | L14: 4 | M14: 4 | N14: 4 | O14: 5 | P14: 5 | Q14: 3 | R14: 1 | S14: =IF(E14="Ngoài HN",1,IF(E14="","",6-VALUE(E14))) -> 4 | T14: 4 | U14: 3 | V14: =ROUND(SUMPRODUCT(K14:U14,$K$3:$U$3)/(5*SUM($K$3:$U$3))*100,1) -> 70.6 | W14: =IF(E14="Ngoài HN","Đợt 4 – Ngoài HN",IF(V14>='Trọng số'!$C$19,"Đợt 1",IF(V14>='Trọng số'!$C$20,"Đợt 2","Đợt 3"))) -> Đợt 1 | X14: =IF(K14>=4,"LMS + số hóa học liệu",IF(K14=3,"Nâng cấp/thay LMS + số hóa học liệu","Số hóa học liệu, chạy trên LMS sẵn có"))&IF(L14>=4," + mô phỏng","")&IF(M14>=4," + ngoại ngữ","") -> Nâng cấp/thay LMS + số hóa học liệu + mô phỏng + ngoại ngữ | Y14: Ước lượng – LMS/quy mô cần khảo sát | Z14: C1=3: chưa rõ, giả định có LMS/Moodle cơ bản | C2=4: khớp: y tế, lab khoa học | C3=4: Đề án 2371 + chuẩn đầu ra tiếng Anh ĐH | C4=4: khối lượng giáo trình lớn | C5=5: rất lớn | C6=5: Tư thục | C7=3: Đề án 2371 | C8=1: chưa có quan hệ (tự cập nhật) | C9=4: Vùng 2 (ước lượng) | C10=4: hạ tầng khá | C11=3: trường trung bình | AC14: Bổ sung
A15: =RANK(V15,$V$5:$V$101) -> 11 | B15: CĐ Công nghệ và Thương mại Hà Nội (HTT) | C15: Cao đẳng | D15: Tư thục | E15: 3 | F15: 13.5 | G15: Kỹ thuật Điện - Điện tử, Tự động hóa, Công nghệ Ô tô, CNTT | H15: Có E-learning cơ bản. Hỗ trợ sinh viên học các học phần lý thuyết từ xa. | I15: Khá. Đã có cổng thông tin tra cứu điểm thi và nộp hồ sơ nhập học online. | J15: Không có sự kiện riêng; chỉ có động lực chính sách chung | K15: 4 | L15: 5 | M15: 5 | N15: 4 | O15: 3 | P15: 5 | Q15: 2 | R15: 1 | S15: =IF(E15="Ngoài HN",1,IF(E15="","",6-VALUE(E15))) -> 3 | T15: 4 | U15: 3 | V15: =ROUND(SUMPRODUCT(K15:U15,$K$3:$U$3)/(5*SUM($K$3:$U$3))*100,1) -> 70.2 | W15: =IF(E15="Ngoài HN","Đợt 4 – Ngoài HN",IF(V15>='Trọng số'!$C$19,"Đợt 1",IF(V15>='Trọng số'!$C$20,"Đợt 2","Đợt 3"))) -> Đợt 1 | X15: =IF(K15>=4,"LMS + số hóa học liệu",IF(K15=3,"Nâng cấp/thay LMS + số hóa học liệu","Số hóa học liệu, chạy trên LMS sẵn có"))&IF(L15>=4," + mô phỏng","")&IF(M15>=4," + ngoại ngữ","") -> LMS + số hóa học liệu + mô phỏng + ngoại ngữ | Y15: Chưa xác minh (file gốc) | Z15: C1=4: LMS mức cơ bản | C2=5: khớp: điện–điện tử, cơ khí/ô tô/thiết bị, lab khoa học | C3=5: ngành du lịch/thương mại/liên kết Hàn: ngoại ngữ là năng lực nghề | C4=4: trường nghề nặng thực hành, học liệu chủ yếu giấy/PDF | C5=3: trung bình/chưa rõ | C6=5: Tư thục | C7=2: Không có sự kiện riêng; chỉ có động lực chính sách chung | C8=1: chưa có quan hệ (tự cập nhật) | C9=3: Vùng 3 | C10=4: số hóa quản lý khá | C11=3: trường trong mạng lưới | AB15: htt.edu.vn | AC15: File gốc #36
A16: =RANK(V16,$V$5:$V$101) -> 11 | B16: Trường ĐH Đại Nam | C16: Đại học | D16: Tư thục | E16: 1 | G16: Y dược, điều dưỡng, CNTT, ngôn ngữ | H16: Cần khảo sát (chưa rõ, giả định có LMS/Moodle cơ bản) | I16: Cần khảo sát | J16: Đề án 2371: chuẩn đầu ra tiếng Anh | K16: 3 | L16: 4 | M16: 4 | N16: 4 | O16: 4 | P16: 5 | Q16: 3 | R16: 1 | S16: =IF(E16="Ngoài HN",1,IF(E16="","",6-VALUE(E16))) -> 5 | T16: 4 | U16: 3 | V16: =ROUND(SUMPRODUCT(K16:U16,$K$3:$U$3)/(5*SUM($K$3:$U$3))*100,1) -> 70.2 | W16: =IF(E16="Ngoài HN","Đợt 4 – Ngoài HN",IF(V16>='Trọng số'!$C$19,"Đợt 1",IF(V16>='Trọng số'!$C$20,"Đợt 2","Đợt 3"))) -> Đợt 1 | X16: =IF(K16>=4,"LMS + số hóa học liệu",IF(K16=3,"Nâng cấp/thay LMS + số hóa học liệu","Số hóa học liệu, chạy trên LMS sẵn có"))&IF(L16>=4," + mô phỏng","")&IF(M16>=4," + ngoại ngữ","") -> Nâng cấp/thay LMS + số hóa học liệu + mô phỏng + ngoại ngữ | Y16: Ước lượng – LMS/quy mô cần khảo sát | Z16: C1=3: chưa rõ, giả định có LMS/Moodle cơ bản | C2=4: khớp: y tế, lab khoa học | C3=4: Đề án 2371 + chuẩn đầu ra tiếng Anh ĐH | C4=4: khối lượng giáo trình lớn | C5=4: lớn | C6=5: Tư thục | C7=3: Đề án 2371: chuẩn đầu ra tiếng Anh | C8=1: chưa có quan hệ (tự cập nhật) | C9=5: Vùng 1 (ước lượng) | C10=4: hạ tầng khá | C11=3: trường trung bình | AC16: Bổ sung
A17: =RANK(V17,$V$5:$V$101) -> 13 | B17: CĐ Y Dược Tuệ Tĩnh Hà Nội | C17: Cao đẳng | D17: Tư thục | E17: 1 | F17: 2 | G17: Y học cổ truyền, Dược học, Kỹ thuật Điều dưỡng | H17: Chưa có LMS chuyên biệt. Thông báo học tập qua website và lớp học Google Classroom. | I17: Trung bình. Tiếp nhận hồ sơ qua cổng Đăng ký trực tuyến. | J17: Không có sự kiện riêng; chỉ có động lực chính sách chung | K17: 5 | L17: 4 | M17: 4 | N17: 4 | O17: 3 | P17: 5 | Q17: 2 | R17: 1 | S17: =IF(E17="Ngoài HN",1,IF(E17="","",6-VALUE(E17))) -> 5 | T17: 3 | U17: 3 | V17: =ROUND(SUMPRODUCT(K17:U17,$K$3:$U$3)/(5*SUM($K$3:$U$3))*100,1) -> 70 | W17: =IF(E17="Ngoài HN","Đợt 4 – Ngoài HN",IF(V17>='Trọng số'!$C$19,"Đợt 1",IF(V17>='Trọng số'!$C$20,"Đợt 2","Đợt 3"))) -> Đợt 1 | X17: =IF(K17>=4,"LMS + số hóa học liệu",IF(K17=3,"Nâng cấp/thay LMS + số hóa học liệu","Số hóa học liệu, chạy trên LMS sẵn có"))&IF(L17>=4," + mô phỏng","")&IF(M17>=4," + ngoại ngữ","") -> LMS + số hóa học liệu + mô phỏng + ngoại ngữ | Y17: Chưa xác minh (file gốc) | Z17: C1=5: chưa có LMS (theo file) | C2=4: khớp: y tế, lab khoa học | C3=4: điều dưỡng/y tế: nhu cầu tiếng Nhật/Đức/Anh để làm việc nước ngoài | C4=4: trường nghề nặng thực hành, học liệu chủ yếu giấy/PDF | C5=3: trung bình/chưa rõ | C6=5: Tư thục | C7=2: Không có sự kiện riêng; chỉ có động lực chính sách chung | C8=1: chưa có quan hệ (tự cập nhật) | C9=5: Vùng 1 | C10=3: số hóa trung bình | C11=3: trường trong mạng lưới | AB17: tuetinh.edu.vn | AC17: File gốc #2
A18: =RANK(V18,$V$5:$V$101) -> 13 | B18: CĐ Y Dược Hà Nội (Phân viện Triều Khúc) | C18: Cao đẳng | D18: Tư thục (cần xác minh) | E18: 1 | F18: 5 | G18: Dược, Điều dưỡng, Kỹ thuật Phục hồi chức năng | H18: Chưa có LMS thực hành. Mới có kho tài liệu số trên web. | I18: Trung bình. Có cổng xét tuyển trực tuyến và quản lý hồ sơ tân sinh viên. | J18: Không có sự kiện riêng; chỉ có động lực chính sách chung | K18: 5 | L18: 4 | M18: 4 | N18: 4 | O18: 3 | P18: 5 | Q18: 2 | R18: 1 | S18: =IF(E18="Ngoài HN",1,IF(E18="","",6-VALUE(E18))) -> 5 | T18: 3 | U18: 3 | V18: =ROUND(SUMPRODUCT(K18:U18,$K$3:$U$3)/(5*SUM($K$3:$U$3))*100,1) -> 70 | W18: =IF(E18="Ngoài HN","Đợt 4 – Ngoài HN",IF(V18>='Trọng số'!$C$19,"Đợt 1",IF(V18>='Trọng số'!$C$20,"Đợt 2","Đợt 3"))) -> Đợt 1 | X18: =IF(K18>=4,"LMS + số hóa học liệu",IF(K18=3,"Nâng cấp/thay LMS + số hóa học liệu","Số hóa học liệu, chạy trên LMS sẵn có"))&IF(L18>=4," + mô phỏng","")&IF(M18>=4," + ngoại ngữ","") -> LMS + số hóa học liệu + mô phỏng + ngoại ngữ | Y18: Chưa xác minh tên/cơ sở | Z18: C1=5: chưa có LMS (theo file) | C2=4: khớp: y tế, lab khoa học | C3=4: điều dưỡng/y tế: nhu cầu tiếng Nhật/Đức/Anh để làm việc nước ngoài | C4=4: trường nghề nặng thực hành, học liệu chủ yếu giấy/PDF | C5=3: trung bình/chưa rõ | C6=5: Tư thục (cần xác minh) | C7=2: Không có sự kiện riêng; chỉ có động lực chính sách chung | C8=1: chưa có quan hệ (tự cập nhật) | C9=5: Vùng 1 | C10=3: số hóa trung bình | C11=3: trường trong mạng lưới | AB18: cdyduochanoi.edu.vn | AC18: File gốc #8
A19: =RANK(V19,$V$5:$V$101) -> 13 | B19: Trường ĐH Thủy lợi | C19: Đại học | D19: Công lập – Bộ NN&MT | E19: 2 | G19: Xây dựng, cơ khí, điện, môi trường | H19: Cần khảo sát (chưa rõ, giả định có LMS/Moodle cơ bản) | I19: Cần khảo sát | J19: Đề án 2371 | K19: 3 | L19: 5 | M19: 4 | N19: 4 | O19: 5 | P19: 3 | Q19: 3 | R19: 1 | S19: =IF(E19="Ngoài HN",1,IF(E19="","",6-VALUE(E19))) -> 4 | T19: 4 | U19: 4 | V19: =ROUND(SUMPRODUCT(K19:U19,$K$3:$U$3)/(5*SUM($K$3:$U$3))*100,1) -> 70 | W19: =IF(E19="Ngoài HN","Đợt 4 – Ngoài HN",IF(V19>='Trọng số'!$C$19,"Đợt 1",IF(V19>='Trọng số'!$C$20,"Đợt 2","Đợt 3"))) -> Đợt 1 | X19: =IF(K19>=4,"LMS + số hóa học liệu",IF(K19=3,"Nâng cấp/thay LMS + số hóa học liệu","Số hóa học liệu, chạy trên LMS sẵn có"))&IF(L19>=4," + mô phỏng","")&IF(M19>=4," + ngoại ngữ","") -> Nâng cấp/thay LMS + số hóa học liệu + mô phỏng + ngoại ngữ | Y19: Ước lượng – LMS/quy mô cần khảo sát | Z19: C1=3: chưa rõ, giả định có LMS/Moodle cơ bản | C2=5: khớp: điện–điện tử, cơ khí/ô tô/thiết bị, lab khoa học | C3=4: Đề án 2371 + chuẩn đầu ra tiếng Anh ĐH | C4=4: khối lượng giáo trình lớn | C5=5: rất lớn | C6=3: Công lập – Bộ NN&MT | C7=3: Đề án 2371 | C8=1: chưa có quan hệ (tự cập nhật) | C9=4: Vùng 2 (ước lượng) | C10=4: hạ tầng khá | C11=4: uy tín trong khối ngành | AC19: Bổ sung
A20: =RANK(V20,$V$5:$V$101) -> 13 | B20: Trường ĐH Dược Hà Nội | C20: Đại học | D20: Công lập – Bộ Y tế | E20: 3 | G20: Dược, hóa dược, công nghệ sinh học | H20: Cần khảo sát (chưa rõ, giả định có LMS/Moodle cơ bản) | I20: Cần khảo sát | J20: Đề án 2371 | K20: 3 | L20: 4 | M20: 4 | N20: 4 | O20: 4 | P20: 4 | Q20: 3 | R20: 1 | S20: =IF(E20="Ngoài HN",1,IF(E20="","",6-VALUE(E20))) -> 3 | T20: 5 | U20: 5 | V20: =ROUND(SUMPRODUCT(K20:U20,$K$3:$U$3)/(5*SUM($K$3:$U$3))*100,1) -> 70 | W20: =IF(E20="Ngoài HN","Đợt 4 – Ngoài HN",IF(V20>='Trọng số'!$C$19,"Đợt 1",IF(V20>='Trọng số'!$C$20,"Đợt 2","Đợt 3"))) -> Đợt 1 | X20: =IF(K20>=4,"LMS + số hóa học liệu",IF(K20=3,"Nâng cấp/thay LMS + số hóa học liệu","Số hóa học liệu, chạy trên LMS sẵn có"))&IF(L20>=4," + mô phỏng","")&IF(M20>=4," + ngoại ngữ","") -> Nâng cấp/thay LMS + số hóa học liệu + mô phỏng + ngoại ngữ | Y20: Ước lượng – LMS/quy mô cần khảo sát | Z20: C1=3: chưa rõ, giả định có LMS/Moodle cơ bản | C2=4: khớp: y tế, lab khoa học | C3=4: Đề án 2371 + chuẩn đầu ra tiếng Anh ĐH | C4=4: khối lượng giáo trình lớn | C5=4: lớn | C6=4: Công lập – Bộ Y tế | C7=3: Đề án 2371 | C8=1: chưa có quan hệ (tự cập nhật) | C9=3: Vùng 3 (ước lượng) | C10=5: hạ tầng CNTT mạnh | C11=5: thương hiệu đầu ngành | AC20: Bổ sung
A21: =RANK(V21,$V$5:$V$101) -> 17 | B21: Học viện Công nghệ Bưu chính Viễn thông (PTIT) | C21: Đại học | D21: Công lập – tự chủ | E21: 1 | G21: Điện tử viễn thông, CNTT, đa phương tiện | H21: Cần khảo sát (nhiều khả năng đã có LMS (giả định)) | I21: Cần khảo sát | J21: Đề án 2371: chuẩn đầu ra tiếng Anh | K21: 2 | L21: 4 | M21: 5 | N21: 3 | O21: 5 | P21: 4 | Q21: 3 | R21: 1 | S21: =IF(E21="Ngoài HN",1,IF(E21="","",6-VALUE(E21))) -> 5 | T21: 5 | U21: 4 | V21: =ROUND(SUMPRODUCT(K21:U21,$K$3:$U$3)/(5*SUM($K$3:$U$3))*100,1) -> 69.8 | W21: =IF(E21="Ngoài HN","Đợt 4 – Ngoài HN",IF(V21>='Trọng số'!$C$19,"Đợt 1",IF(V21>='Trọng số'!$C$20,"Đợt 2","Đợt 3"))) -> Đợt 2 | X21: =IF(K21>=4,"LMS + số hóa học liệu",IF(K21=3,"Nâng cấp/thay LMS + số hóa học liệu","Số hóa học liệu, chạy trên LMS sẵn có"))&IF(L21>=4," + mô phỏng","")&IF(M21>=4," + ngoại ngữ","") -> Số hóa học liệu, chạy trên LMS sẵn có + mô phỏng + ngoại ngữ | Y21: Ước lượng – LMS/quy mô cần khảo sát | Z21: C1=2: nhiều khả năng đã có LMS (giả định) | C2=4: khớp: điện–điện tử | C3=5: Đề án 2371 + chuẩn đầu ra tiếng Anh ĐH | C4=3: đã có một phần học liệu số | C5=5: rất lớn | C6=4: Công lập – tự chủ | C7=3: Đề án 2371: chuẩn đầu ra tiếng Anh | C8=1: chưa có quan hệ (tự cập nhật) | C9=5: Vùng 1 (ước lượng) | C10=5: hạ tầng CNTT mạnh | C11=4: uy tín trong khối ngành | AA21: Mạnh CNTT, có thể tự làm LMS; chào khóa ngoại ngữ + mô phỏng mạch | AC21: Bổ sung
A22: =RANK(V22,$V$5:$V$101) -> 18 | B22: CĐ Y Dược Pasteur Hà Nội (CS Hà Đông) | C22: Cao đẳng | D22: Tư thục | E22: 1 | F22: 4.5 | G22: Dược, Điều dưỡng, Kỹ thuật Xét nghiệm, Hộ sinh | H22: Có E-learning lý thuyết. Đào tạo trực tuyến các học phần cơ sở ngành. | I22: Tốt khâu tuyển sinh. Hệ thống CRM tuyển sinh online phủ sóng toàn quốc. | J22: Không có sự kiện riêng; chỉ có động lực chính sách chung | K22: 3 | L22: 4 | M22: 4 | N22: 4 | O22: 4 | P22: 5 | Q22: 2 | R22: 1 | S22: =IF(E22="Ngoài HN",1,IF(E22="","",6-VALUE(E22))) -> 5 | T22: 5 | U22: 3 | V22: =ROUND(SUMPRODUCT(K22:U22,$K$3:$U$3)/(5*SUM($K$3:$U$3))*100,1) -> 69.6 | W22: =IF(E22="Ngoài HN","Đợt 4 – Ngoài HN",IF(V22>='Trọng số'!$C$19,"Đợt 1",IF(V22>='Trọng số'!$C$20,"Đợt 2","Đợt 3"))) -> Đợt 2 | X22: =IF(K22>=4,"LMS + số hóa học liệu",IF(K22=3,"Nâng cấp/thay LMS + số hóa học liệu","Số hóa học liệu, chạy trên LMS sẵn có"))&IF(L22>=4," + mô phỏng","")&IF(M22>=4," + ngoại ngữ","") -> Nâng cấp/thay LMS + số hóa học liệu + mô phỏng + ngoại ngữ | Y22: Chưa xác minh (file gốc) | Z22: C1=3: có e-learning lý thuyết | C2=4: khớp: y tế, lab khoa học | C3=4: điều dưỡng/y tế: nhu cầu tiếng Nhật/Đức/Anh để làm việc nước ngoài | C4=4: trường nghề nặng thực hành, học liệu chủ yếu giấy/PDF | C5=4: lớn, nhiều ngành | C6=5: Tư thục | C7=2: Không có sự kiện riêng; chỉ có động lực chính sách chung | C8=1: chưa có quan hệ (tự cập nhật) | C9=5: Vùng 1 | C10=5: đã số hóa quản lý tốt | C11=3: trường trong mạng lưới | AB22: caodangyduocpasteur.com.vn | AC22: File gốc #6
A23: =RANK(V23,$V$5:$V$101) -> 18 | B23: CĐ Ngoại ngữ và Công nghệ Việt Nam | C23: Cao đẳng | D23: Tư thục | E23: 3 | F23: 14 | G23: Kỹ thuật chế biến, Công nghệ Ô tô, CNTT, Kỹ thuật điện | H23: Chưa có LMS thực hành. Đang sử dụng các phần mềm họp trực tuyến bổ trợ. | I23: Trung bình. Hệ thống tuyển sinh online khá năng động qua landing page và mạng xã hội. | J23: Không có sự kiện riêng; chỉ có động lực chính sách chung | K23: 5 | L23: 5 | M23: 4 | N23: 4 | O23: 3 | P23: 5 | Q23: 2 | R23: 1 | S23: =IF(E23="Ngoài HN",1,IF(E23="","",6-VALUE(E23))) -> 3 | T23: 3 | U23: 3 | V23: =ROUND(SUMPRODUCT(K23:U23,$K$3:$U$3)/(5*SUM($K$3:$U$3))*100,1) -> 69.6 | W23: =IF(E23="Ngoài HN","Đợt 4 – Ngoài HN",IF(V23>='Trọng số'!$C$19,"Đợt 1",IF(V23>='Trọng số'!$C$20,"Đợt 2","Đợt 3"))) -> Đợt 2 | X23: =IF(K23>=4,"LMS + số hóa học liệu",IF(K23=3,"Nâng cấp/thay LMS + số hóa học liệu","Số hóa học liệu, chạy trên LMS sẵn có"))&IF(L23>=4," + mô phỏng","")&IF(M23>=4," + ngoại ngữ","") -> LMS + số hóa học liệu + mô phỏng + ngoại ngữ | Y23: Chưa xác minh (file gốc) | Z23: C1=5: chưa có LMS (theo file) | C2=5: khớp: điện–điện tử, cơ khí/ô tô/thiết bị, lab khoa học | C3=4: trường có thế mạnh ngoại ngữ, có thể là đối thủ ở mảng khóa ngoại ngữ | C4=4: trường nghề nặng thực hành, học liệu chủ yếu giấy/PDF | C5=3: trung bình/chưa rõ | C6=5: Tư thục | C7=2: Không có sự kiện riêng; chỉ có động lực chính sách chung | C8=1: chưa có quan hệ (tự cập nhật) | C9=3: Vùng 3 | C10=3: số hóa trung bình | C11=3: trường trong mạng lưới | AB23: caodangngoaingu.vn | AC23: File gốc #37
A24: =RANK(V24,$V$5:$V$101) -> 20 | B24: CĐ Dược Hà Nội (Cơ sở Hà Đông) | C24: Cao đẳng | D24: Tư thục (cần xác minh) | E24: 1 | F24: 4.8 | G24: Kỹ thuật Dược, Điều dưỡng, Kỹ thuật Vật lý trị liệu | H24: LMS mức cơ bản. Dùng hệ thống E-learning để trả bài kiểm tra trắc nghiệm. | I24: Khá. Quản lý dữ liệu sinh viên và đóng học phí trực tuyến qua cổng web. | J24: Không có sự kiện riêng; chỉ có động lực chính sách chung | K24: 4 | L24: 4 | M24: 4 | N24: 4 | O24: 3 | P24: 5 | Q24: 2 | R24: 1 | S24: =IF(E24="Ngoài HN",1,IF(E24="","",6-VALUE(E24))) -> 5 | T24: 4 | U24: 3 | V24: =ROUND(SUMPRODUCT(K24:U24,$K$3:$U$3)/(5*SUM($K$3:$U$3))*100,1) -> 69 | W24: =IF(E24="Ngoài HN","Đợt 4 – Ngoài HN",IF(V24>='Trọng số'!$C$19,"Đợt 1",IF(V24>='Trọng số'!$C$20,"Đợt 2","Đợt 3"))) -> Đợt 2 | X24: =IF(K24>=4,"LMS + số hóa học liệu",IF(K24=3,"Nâng cấp/thay LMS + số hóa học liệu","Số hóa học liệu, chạy trên LMS sẵn có"))&IF(L24>=4," + mô phỏng","")&IF(M24>=4," + ngoại ngữ","") -> LMS + số hóa học liệu + mô phỏng + ngoại ngữ | Y24: Chưa xác minh tên/cơ sở | Z24: C1=4: LMS mức cơ bản | C2=4: khớp: y tế, lab khoa học | C3=4: điều dưỡng/y tế: nhu cầu tiếng Nhật/Đức/Anh để làm việc nước ngoài | C4=4: trường nghề nặng thực hành, học liệu chủ yếu giấy/PDF | C5=3: trung bình/chưa rõ | C6=5: Tư thục (cần xác minh) | C7=2: Không có sự kiện riêng; chỉ có động lực chính sách chung | C8=1: chưa có quan hệ (tự cập nhật) | C9=5: Vùng 1 | C10=4: số hóa quản lý khá | C11=3: trường trong mạng lưới | AB24: duochanoi.edu.vn | AC24: File gốc #7
A25: =RANK(V25,$V$5:$V$101) -> 20 | B25: Trường ĐH Thăng Long | C25: Đại học | D25: Tư thục | E25: 2 | G25: Điều dưỡng, y tế công cộng, CNTT, ngôn ngữ | H25: Cần khảo sát (chưa rõ, giả định có LMS/Moodle cơ bản) | I25: Cần khảo sát | J25: Đề án 2371 | K25: 3 | L25: 4 | M25: 4 | N25: 4 | O25: 4 | P25: 5 | Q25: 3 | R25: 1 | S25: =IF(E25="Ngoài HN",1,IF(E25="","",6-VALUE(E25))) -> 4 | T25: 4 | U25: 3 | V25: =ROUND(SUMPRODUCT(K25:U25,$K$3:$U$3)/(5*SUM($K$3:$U$3))*100,1) -> 69 | W25: =IF(E25="Ngoài HN","Đợt 4 – Ngoài HN",IF(V25>='Trọng số'!$C$19,"Đợt 1",IF(V25>='Trọng số'!$C$20,"Đợt 2","Đợt 3"))) -> Đợt 2 | X25: =IF(K25>=4,"LMS + số hóa học liệu",IF(K25=3,"Nâng cấp/thay LMS + số hóa học liệu","Số hóa học liệu, chạy trên LMS sẵn có"))&IF(L25>=4," + mô phỏng","")&IF(M25>=4," + ngoại ngữ","") -> Nâng cấp/thay LMS + số hóa học liệu + mô phỏng + ngoại ngữ | Y25: Ước lượng – LMS/quy mô cần khảo sát | Z25: C1=3: chưa rõ, giả định có LMS/Moodle cơ bản | C2=4: khớp: y tế | C3=4: Đề án 2371 + chuẩn đầu ra tiếng Anh ĐH | C4=4: khối lượng giáo trình lớn | C5=4: lớn | C6=5: Tư thục | C7=3: Đề án 2371 | C8=1: chưa có quan hệ (tự cập nhật) | C9=4: Vùng 2 (ước lượng) | C10=4: hạ tầng khá | C11=3: trường trung bình | AC25: Bổ sung
A26: =RANK(V26,$V$5:$V$101) -> 20 | B26: Trường ĐH Mở Hà Nội | C26: Đại học | D26: Công lập – Bộ GD&ĐT | E26: 2 | G26: Đào tạo từ xa/trực tuyến, ngôn ngữ, CNTT, điện tử | H26: Cần khảo sát (nhiều khả năng đã có LMS (giả định)) | I26: Cần khảo sát | J26: Đề án 2371 | K26: 2 | L26: 3 | M26: 4 | N26: 5 | O26: 5 | P26: 4 | Q26: 3 | R26: 1 | S26: =IF(E26="Ngoài HN",1,IF(E26="","",6-VALUE(E26))) -> 4 | T26: 5 | U26: 4 | V26: =ROUND(SUMPRODUCT(K26:U26,$K$3:$U$3)/(5*SUM($K$3:$U$3))*100,1) -> 69 | W26: =IF(E26="Ngoài HN","Đợt 4 – Ngoài HN",IF(V26>='Trọng số'!$C$19,"Đợt 1",IF(V26>='Trọng số'!$C$20,"Đợt 2","Đợt 3"))) -> Đợt 2 | X26: =IF(K26>=4,"LMS + số hóa học liệu",IF(K26=3,"Nâng cấp/thay LMS + số hóa học liệu","Số hóa học liệu, chạy trên LMS sẵn có"))&IF(L26>=4," + mô phỏng","")&IF(M26>=4," + ngoại ngữ","") -> Số hóa học liệu, chạy trên LMS sẵn có + ngoại ngữ | Y26: Ước lượng – LMS/quy mô cần khảo sát | Z26: C1=2: nhiều khả năng đã có LMS (giả định) | C2=3: khớp: điện–điện tử | C3=4: Đề án 2371 + chuẩn đầu ra tiếng Anh ĐH | C4=5: khối lượng học liệu rất lớn (đào tạo từ xa) | C5=5: rất lớn | C6=4: Công lập – Bộ GD&ĐT | C7=3: Đề án 2371 | C8=1: chưa có quan hệ (tự cập nhật) | C9=4: Vùng 2 (ước lượng) | C10=5: hạ tầng CNTT mạnh | C11=4: uy tín trong khối ngành | AA26: Mạnh đào tạo trực tuyến: vừa là khách hàng số hóa học liệu, vừa có thể là đối thủ/đối tác | AC26: Bổ sung
A27: =RANK(V27,$V$5:$V$101) -> 23 | B27: Trường ĐH Kinh tế – Kỹ thuật Công nghiệp (UNETI) | C27: Đại học | D27: Công lập – Bộ Công Thương | E27: 2 | G27: Điện, điện tử, cơ khí, dệt may, thực phẩm | H27: Cần khảo sát (chưa rõ, giả định có LMS/Moodle cơ bản) | I27: Cần khảo sát | J27: Đề án 2371 | K27: 3 | L27: 5 | M27: 4 | N27: 4 | O27: 5 | P27: 3 | Q27: 3 | R27: 1 | S27: =IF(E27="Ngoài HN",1,IF(E27="","",6-VALUE(E27))) -> 4 | T27: 4 | U27: 3 | V27: =ROUND(SUMPRODUCT(K27:U27,$K$3:$U$3)/(5*SUM($K$3:$U$3))*100,1) -> 68.6 | W27: =IF(E27="Ngoài HN","Đợt 4 – Ngoài HN",IF(V27>='Trọng số'!$C$19,"Đợt 1",IF(V27>='Trọng số'!$C$20,"Đợt 2","Đợt 3"))) -> Đợt 2 | X27: =IF(K27>=4,"LMS + số hóa học liệu",IF(K27=3,"Nâng cấp/thay LMS + số hóa học liệu","Số hóa học liệu, chạy trên LMS sẵn có"))&IF(L27>=4," + mô phỏng","")&IF(M27>=4," + ngoại ngữ","") -> Nâng cấp/thay LMS + số hóa học liệu + mô phỏng + ngoại ngữ | Y27: Ước lượng – LMS/quy mô cần khảo sát | Z27: C1=3: chưa rõ, giả định có LMS/Moodle cơ bản | C2=5: khớp: điện–điện tử, cơ khí/ô tô/thiết bị | C3=4: Đề án 2371 + chuẩn đầu ra tiếng Anh ĐH | C4=4: khối lượng giáo trình lớn | C5=5: rất lớn | C6=3: Công lập – Bộ Công Thương | C7=3: Đề án 2371 | C8=1: chưa có quan hệ (tự cập nhật) | C9=4: Vùng 2 (ước lượng) | C10=4: hạ tầng khá | C11=3: trường trung bình | AC27: Bổ sung
A28: =RANK(V28,$V$5:$V$101) -> 23 | B28: Học viện Nông nghiệp Việt Nam | C28: Đại học | D28: Công lập – tự chủ | E28: 4 | G28: Nông nghiệp, cơ điện, công nghệ sinh học, thú y | H28: Cần khảo sát (nhiều khả năng đã có LMS (giả định)) | I28: Cần khảo sát | J28: Đề án 2371 | K28: 2 | L28: 5 | M28: 4 | N28: 4 | O28: 5 | P28: 4 | Q28: 3 | R28: 1 | S28: =IF(E28="Ngoài HN",1,IF(E28="","",6-VALUE(E28))) -> 2 | T28: 5 | U28: 4 | V28: =ROUND(SUMPRODUCT(K28:U28,$K$3:$U$3)/(5*SUM($K$3:$U$3))*100,1) -> 68.6 | W28: =IF(E28="Ngoài HN","Đợt 4 – Ngoài HN",IF(V28>='Trọng số'!$C$19,"Đợt 1",IF(V28>='Trọng số'!$C$20,"Đợt 2","Đợt 3"))) -> Đợt 2 | X28: =IF(K28>=4,"LMS + số hóa học liệu",IF(K28=3,"Nâng cấp/thay LMS + số hóa học liệu","Số hóa học liệu, chạy trên LMS sẵn có"))&IF(L28>=4," + mô phỏng","")&IF(M28>=4," + ngoại ngữ","") -> Số hóa học liệu, chạy trên LMS sẵn có + mô phỏng + ngoại ngữ | Y28: Ước lượng – LMS/quy mô cần khảo sát | Z28: C1=2: nhiều khả năng đã có LMS (giả định) | C2=5: khớp: điện–điện tử, lab khoa học | C3=4: Đề án 2371 + chuẩn đầu ra tiếng Anh ĐH | C4=4: khối lượng giáo trình lớn | C5=5: rất lớn | C6=4: Công lập – tự chủ | C7=3: Đề án 2371 | C8=1: chưa có quan hệ (tự cập nhật) | C9=2: Vùng 4 (ước lượng) | C10=5: hạ tầng CNTT mạnh | C11=4: uy tín trong khối ngành | AC28: Bổ sung
A29: =RANK(V29,$V$5:$V$101) -> 25 | B29: TT GDNN-GDTX khu vực Hà Đông – Chương Mỹ | C29: TT GDNN-GDTX | D29: Công lập – Sở GD&ĐT Hà Nội | E29: 1 | G29: GDTX cấp THPT (Lý, Hóa, Sinh, Tiếng Anh) + nghề ngắn hạn | H29: Cần khảo sát | I29: Cần khảo sát | J29: Hợp nhất từ nhiều TT (29→14) | K29: 5 | L29: 3 | M29: 3 | N29: 5 | O29: 3 | P29: 2 | Q29: 5 | R29: 1 | S29: =IF(E29="Ngoài HN",1,IF(E29="","",6-VALUE(E29))) -> 5 | T29: 2 | U29: 4 | V29: =ROUND(SUMPRODUCT(K29:U29,$K$3:$U$3)/(5*SUM($K$3:$U$3))*100,1) -> 68.4 | W29: =IF(E29="Ngoài HN","Đợt 4 – Ngoài HN",IF(V29>='Trọng số'!$C$19,"Đợt 1",IF(V29>='Trọng số'!$C$20,"Đợt 2","Đợt 3"))) -> Đợt 2 | X29: =IF(K29>=4,"LMS + số hóa học liệu",IF(K29=3,"Nâng cấp/thay LMS + số hóa học liệu","Số hóa học liệu, chạy trên LMS sẵn có"))&IF(L29>=4," + mô phỏng","")&IF(M29>=4," + ngoại ngữ","") -> LMS + số hóa học liệu | Y29: Đã xác minh danh sách khu vực sáp nhập (KH 292); tên mới chưa công bố | Z29: C1=5: giả định chưa có LMS | C2=3: khớp: lab khoa học (chương trình GDTX THPT) | C3=3: tiếng Anh bắt buộc theo chương trình phổ thông | C4=5: hợp nhất học liệu các TT cũ | C5=3: trung bình | C6=2: Ngân sách qua Sở GD&ĐT, quyết định chậm | C7=5: Hợp nhất từ nhiều TT (29→14) | C8=1: chưa có quan hệ (tự cập nhật) | C9=5: Vùng 1 (ước lượng) | C10=2: giả định sơ khai | C11=4: cùng chủ quản với 13 TT khác: thắng 1 dễ nhân rộng | AA29: Cân nhắc tiếp cận cả cụm qua Sở GD&ĐT thay vì từng TT | AC29: Bổ sung
A30: =RANK(V30,$V$5:$V$101) -> 25 | B30: TT GDNN-GDTX khu vực Hoàng Mai – Thanh Xuân | C30: TT GDNN-GDTX | D30: Công lập – Sở GD&ĐT Hà Nội | E30: 1 | G30: GDTX cấp THPT (Lý, Hóa, Sinh, Tiếng Anh) + nghề ngắn hạn | H30: Cần khảo sát | I30: Cần khảo sát | J30: Hợp nhất từ nhiều TT (29→14) | K30: 5 | L30: 3 | M30: 3 | N30: 5 | O30: 3 | P30: 2 | Q30: 5 | R30: 1 | S30: =IF(E30="Ngoài HN",1,IF(E30="","",6-VALUE(E30))) -> 5 | T30: 2 | U30: 4 | V30: =ROUND(SUMPRODUCT(K30:U30,$K$3:$U$3)/(5*SUM($K$3:$U$3))*100,1) -> 68.4 | W30: =IF(E30="Ngoài HN","Đợt 4 – Ngoài HN",IF(V30>='Trọng số'!$C$19,"Đợt 1",IF(V30>='Trọng số'!$C$20,"Đợt 2","Đợt 3"))) -> Đợt 2 | X30: =IF(K30>=4,"LMS + số hóa học liệu",IF(K30=3,"Nâng cấp/thay LMS + số hóa học liệu","Số hóa học liệu, chạy trên LMS sẵn có"))&IF(L30>=4," + mô phỏng","")&IF(M30>=4," + ngoại ngữ","") -> LMS + số hóa học liệu | Y30: Đã xác minh danh sách khu vực sáp nhập (KH 292); tên mới chưa công bố | Z30: C1=5: giả định chưa có LMS | C2=3: khớp: lab khoa học (chương trình GDTX THPT) | C3=3: tiếng Anh bắt buộc theo chương trình phổ thông | C4=5: hợp nhất học liệu các TT cũ | C5=3: trung bình | C6=2: Ngân sách qua Sở GD&ĐT, quyết định chậm | C7=5: Hợp nhất từ nhiều TT (29→14) | C8=1: chưa có quan hệ (tự cập nhật) | C9=5: Vùng 1 (ước lượng) | C10=2: giả định sơ khai | C11=4: cùng chủ quản với 13 TT khác: thắng 1 dễ nhân rộng | AA30: Cân nhắc tiếp cận cả cụm qua Sở GD&ĐT thay vì từng TT | AC30: Bổ sung
A31: =RANK(V31,$V$5:$V$101) -> 25 | B31: Trường ĐH Giao thông vận tải | C31: Đại học | D31: Công lập – tự chủ | E31: 2 | G31: Cơ khí, ô tô, điện – điện tử, xây dựng | H31: Cần khảo sát (nhiều khả năng đã có LMS (giả định)) | I31: Cần khảo sát | J31: Đề án 2371 | K31: 2 | L31: 4 | M31: 4 | N31: 3 | O31: 5 | P31: 4 | Q31: 3 | R31: 1 | S31: =IF(E31="Ngoài HN",1,IF(E31="","",6-VALUE(E31))) -> 4 | T31: 5 | U31: 5 | V31: =ROUND(SUMPRODUCT(K31:U31,$K$3:$U$3)/(5*SUM($K$3:$U$3))*100,1) -> 68.4 | W31: =IF(E31="Ngoài HN","Đợt 4 – Ngoài HN",IF(V31>='Trọng số'!$C$19,"Đợt 1",IF(V31>='Trọng số'!$C$20,"Đợt 2","Đợt 3"))) -> Đợt 2 | X31: =IF(K31>=4,"LMS + số hóa học liệu",IF(K31=3,"Nâng cấp/thay LMS + số hóa học liệu","Số hóa học liệu, chạy trên LMS sẵn có"))&IF(L31>=4," + mô phỏng","")&IF(M31>=4," + ngoại ngữ","") -> Số hóa học liệu, chạy trên LMS sẵn có + mô phỏng + ngoại ngữ | Y31: Ước lượng – LMS/quy mô cần khảo sát | Z31: C1=2: nhiều khả năng đã có LMS (giả định) | C2=4: khớp: điện–điện tử, cơ khí/ô tô/thiết bị | C3=4: Đề án 2371 + chuẩn đầu ra tiếng Anh ĐH | C4=3: đã có một phần học liệu số | C5=5: rất lớn | C6=4: Công lập – tự chủ | C7=3: Đề án 2371 | C8=1: chưa có quan hệ (tự cập nhật) | C9=4: Vùng 2 (ước lượng) | C10=5: hạ tầng CNTT mạnh | C11=5: thương hiệu đầu ngành | AC31: Bổ sung
A32: =RANK(V32,$V$5:$V$101) -> 25 | B32: Trường ĐH Y Hà Nội | C32: Đại học | D32: Công lập – Bộ Y tế | E32: 2 | G32: Y khoa, điều dưỡng, xét nghiệm | H32: Cần khảo sát (nhiều khả năng đã có LMS (giả định)) | I32: Cần khảo sát | J32: Đề án 2371 | K32: 2 | L32: 4 | M32: 4 | N32: 3 | O32: 5 | P32: 4 | Q32: 3 | R32: 1 | S32: =IF(E32="Ngoài HN",1,IF(E32="","",6-VALUE(E32))) -> 4 | T32: 5 | U32: 5 | V32: =ROUND(SUMPRODUCT(K32:U32,$K$3:$U$3)/(5*SUM($K$3:$U$3))*100,1) -> 68.4 | W32: =IF(E32="Ngoài HN","Đợt 4 – Ngoài HN",IF(V32>='Trọng số'!$C$19,"Đợt 1",IF(V32>='Trọng số'!$C$20,"Đợt 2","Đợt 3"))) -> Đợt 2 | X32: =IF(K32>=4,"LMS + số hóa học liệu",IF(K32=3,"Nâng cấp/thay LMS + số hóa học liệu","Số hóa học liệu, chạy trên LMS sẵn có"))&IF(L32>=4," + mô phỏng","")&IF(M32>=4," + ngoại ngữ","") -> Số hóa học liệu, chạy trên LMS sẵn có + mô phỏng + ngoại ngữ | Y32: Ước lượng – LMS/quy mô cần khảo sát | Z32: C1=2: nhiều khả năng đã có LMS (giả định) | C2=4: khớp: y tế, lab khoa học | C3=4: Đề án 2371 + chuẩn đầu ra tiếng Anh ĐH | C4=3: đã có một phần học liệu số | C5=5: rất lớn | C6=4: Công lập – Bộ Y tế | C7=3: Đề án 2371 | C8=1: chưa có quan hệ (tự cập nhật) | C9=4: Vùng 2 (ước lượng) | C10=5: hạ tầng CNTT mạnh | C11=5: thương hiệu đầu ngành | AA32: Chu kỳ bán dài; ưu tiên khi đã có case trường y khác | AC32: Bổ sung
A33: =RANK(V33,$V$5:$V$101) -> 29 | B33: CĐ Y Hà Nội (HMC) | C33: Cao đẳng | D33: Tư thục | E33: 2 | F33: 8.8 | G33: Điều dưỡng, Chăm sóc sắc đẹp, Dược học | H33: Có LMS trực tuyến. Đào tạo các chứng chỉ ngắn hạn và môn khoa học cơ bản. | I33: Khá. Số hóa dữ liệu tuyển sinh và cổng quản lý quá trình thực tập của sinh viên. | J33: Không có sự kiện riêng; chỉ có động lực chính sách chung | K33: 4 | L33: 4 | M33: 4 | N33: 4 | O33: 3 | P33: 5 | Q33: 2 | R33: 1 | S33: =IF(E33="Ngoài HN",1,IF(E33="","",6-VALUE(E33))) -> 4 | T33: 4 | U33: 3 | V33: =ROUND(SUMPRODUCT(K33:U33,$K$3:$U$3)/(5*SUM($K$3:$U$3))*100,1) -> 67.8 | W33: =IF(E33="Ngoài HN","Đợt 4 – Ngoài HN",IF(V33>='Trọng số'!$C$19,"Đợt 1",IF(V33>='Trọng số'!$C$20,"Đợt 2","Đợt 3"))) -> Đợt 2 | X33: =IF(K33>=4,"LMS + số hóa học liệu",IF(K33=3,"Nâng cấp/thay LMS + số hóa học liệu","Số hóa học liệu, chạy trên LMS sẵn có"))&IF(L33>=4," + mô phỏng","")&IF(M33>=4," + ngoại ngữ","") -> LMS + số hóa học liệu + mô phỏng + ngoại ngữ | Y33: Chưa xác minh (file gốc) | Z33: C1=4: LMS mức cơ bản | C2=4: khớp: y tế, lab khoa học | C3=4: điều dưỡng/y tế: nhu cầu tiếng Nhật/Đức/Anh để làm việc nước ngoài | C4=4: trường nghề nặng thực hành, học liệu chủ yếu giấy/PDF | C5=3: trung bình/chưa rõ | C6=5: Tư thục | C7=2: Không có sự kiện riêng; chỉ có động lực chính sách chung | C8=1: chưa có quan hệ (tự cập nhật) | C9=4: Vùng 2 | C10=4: số hóa quản lý khá | C11=3: trường trong mạng lưới | AB33: cdyhn.edu.vn | AC33: File gốc #19
A34: =RANK(V34,$V$5:$V$101) -> 29 | B34: Trung cấp nghề Tổng hợp Hà Nội | C34: Trung cấp | D34: Công lập – TP Hà Nội | E34: 2 | G34: Nghề kỹ thuật (điện, cơ khí, ô tô…) – cần xác minh | H34: Cần khảo sát | I34: Cần khảo sát | J34: Lập đề án nâng cấp lên CĐ đa ngành (KH 292/KH-UBND) | K34: 5 | L34: 4 | M34: 3 | N34: 5 | O34: 3 | P34: 2 | Q34: 5 | R34: 1 | S34: =IF(E34="Ngoài HN",1,IF(E34="","",6-VALUE(E34))) -> 4 | T34: 2 | U34: 3 | V34: =ROUND(SUMPRODUCT(K34:U34,$K$3:$U$3)/(5*SUM($K$3:$U$3))*100,1) -> 67.8 | W34: =IF(E34="Ngoài HN","Đợt 4 – Ngoài HN",IF(V34>='Trọng số'!$C$19,"Đợt 1",IF(V34>='Trọng số'!$C$20,"Đợt 2","Đợt 3"))) -> Đợt 2 | X34: =IF(K34>=4,"LMS + số hóa học liệu",IF(K34=3,"Nâng cấp/thay LMS + số hóa học liệu","Số hóa học liệu, chạy trên LMS sẵn có"))&IF(L34>=4," + mô phỏng","")&IF(M34>=4," + ngoại ngữ","") -> LMS + số hóa học liệu + mô phỏng | Y34: Đã xác minh trong KH 292; vị trí/ngành cần khảo sát | Z34: C1=5: trường trung cấp, nhiều khả năng chưa có LMS | C2=4: khớp: điện–điện tử, cơ khí (giả định) | C3=3: chuẩn đầu ra chung | C4=5: nâng cấp lên cao đẳng: phải xây chương trình/học liệu mới | C5=3: trung bình | C6=2: Công lập – ngân sách TP | C7=5: Đang lập đề án nâng cấp thành cao đẳng đa ngành | C8=1: chưa có quan hệ (tự cập nhật) | C9=4: Vùng 2 (ước lượng) | C10=2: giả định sơ khai | C11=3: thuộc hệ thống trường của TP | AC34: Bổ sung
A35: =RANK(V35,$V$5:$V$101) -> 29 | B35: Trung cấp nghề Giao thông công chính Hà Nội | C35: Trung cấp | D35: Công lập – TP Hà Nội | E35: 2 | G35: Nghề kỹ thuật (điện, cơ khí, ô tô…) – cần xác minh | H35: Cần khảo sát | I35: Cần khảo sát | J35: Lập đề án nâng cấp lên CĐ đa ngành (KH 292/KH-UBND) | K35: 5 | L35: 4 | M35: 3 | N35: 5 | O35: 3 | P35: 2 | Q35: 5 | R35: 1 | S35: =IF(E35="Ngoài HN",1,IF(E35="","",6-VALUE(E35))) -> 4 | T35: 2 | U35: 3 | V35: =ROUND(SUMPRODUCT(K35:U35,$K$3:$U$3)/(5*SUM($K$3:$U$3))*100,1) -> 67.8 | W35: =IF(E35="Ngoài HN","Đợt 4 – Ngoài HN",IF(V35>='Trọng số'!$C$19,"Đợt 1",IF(V35>='Trọng số'!$C$20,"Đợt 2","Đợt 3"))) -> Đợt 2 | X35: =IF(K35>=4,"LMS + số hóa học liệu",IF(K35=3,"Nâng cấp/thay LMS + số hóa học liệu","Số hóa học liệu, chạy trên LMS sẵn có"))&IF(L35>=4," + mô phỏng","")&IF(M35>=4," + ngoại ngữ","") -> LMS + số hóa học liệu + mô phỏng | Y35: Đã xác minh trong KH 292; vị trí/ngành cần khảo sát | Z35: C1=5: trường trung cấp, nhiều khả năng chưa có LMS | C2=4: khớp: điện–điện tử, cơ khí (giả định) | C3=3: chuẩn đầu ra chung | C4=5: nâng cấp lên cao đẳng: phải xây chương trình/học liệu mới | C5=3: trung bình | C6=2: Công lập – ngân sách TP | C7=5: Đang lập đề án nâng cấp thành cao đẳng đa ngành | C8=1: chưa có quan hệ (tự cập nhật) | C9=4: Vùng 2 (ước lượng) | C10=2: giả định sơ khai | C11=3: thuộc hệ thống trường của TP | AC35: Bổ sung
A36: =RANK(V36,$V$5:$V$101) -> 29 | B36: Trường ĐH Thành Đô | C36: Đại học | D36: Tư thục | E36: 3 | G36: Dược, điều dưỡng, ô tô, điện, ngôn ngữ | H36: Cần khảo sát (chưa rõ, giả định LMS sơ khai) | I36: Cần khảo sát | J36: Đề án 2371 | K36: 4 | L36: 5 | M36: 4 | N36: 4 | O36: 3 | P36: 5 | Q36: 3 | R36: 1 | S36: =IF(E36="Ngoài HN",1,IF(E36="","",6-VALUE(E36))) -> 3 | T36: 3 | U36: 2 | V36: =ROUND(SUMPRODUCT(K36:U36,$K$3:$U$3)/(5*SUM($K$3:$U$3))*100,1) -> 67.8 | W36: =IF(E36="Ngoài HN","Đợt 4 – Ngoài HN",IF(V36>='Trọng số'!$C$19,"Đợt 1",IF(V36>='Trọng số'!$C$20,"Đợt 2","Đợt 3"))) -> Đợt 2 | X36: =IF(K36>=4,"LMS + số hóa học liệu",IF(K36=3,"Nâng cấp/thay LMS + số hóa học liệu","Số hóa học liệu, chạy trên LMS sẵn có"))&IF(L36>=4," + mô phỏng","")&IF(M36>=4," + ngoại ngữ","") -> LMS + số hóa học liệu + mô phỏng + ngoại ngữ | Y36: Ước lượng – LMS/quy mô cần khảo sát | Z36: C1=4: chưa rõ, giả định LMS sơ khai | C2=5: khớp: điện–điện tử, cơ khí/ô tô/thiết bị, y tế, lab khoa học | C3=4: Đề án 2371 + chuẩn đầu ra tiếng Anh ĐH | C4=4: khối lượng giáo trình lớn | C5=3: trung bình | C6=5: Tư thục | C7=3: Đề án 2371 | C8=1: chưa có quan hệ (tự cập nhật) | C9=3: Vùng 3 (ước lượng) | C10=3: hạ tầng trung bình | C11=2: ít giá trị tham chiếu | AC36: Bổ sung
A37: =RANK(V37,$V$5:$V$101) -> 33 | B37: CĐ nghề Bách Khoa Hà Nội (HACTECH) | C37: Cao đẳng | D37: Tư thục | E37: 3 | F37: 11.5 | G37: Điện tử công nghiệp, Cơ điện tử, Vi điều khiển, Ô tô, CNTT | H37: Hệ thống quản trị hồ sơ bài bản: sinhvien.hactech.edu.vn. Quản lý tuyển sinh: hactech.edu.vn/tuyen-sinh. | I37: Đã số hóa hoàn chỉnh. Cơ sở dữ liệu học vụ, điểm số và hồ sơ sinh viên đồng bộ chặt chẽ. | J37: Không có sự kiện riêng; chỉ có động lực chính sách chung | K37: 3 | L37: 5 | M37: 3 | N37: 4 | O37: 4 | P37: 5 | Q37: 2 | R37: 1 | S37: =IF(E37="Ngoài HN",1,IF(E37="","",6-VALUE(E37))) -> 3 | T37: 5 | U37: 3 | V37: =ROUND(SUMPRODUCT(K37:U37,$K$3:$U$3)/(5*SUM($K$3:$U$3))*100,1) -> 67.6 | W37: =IF(E37="Ngoài HN","Đợt 4 – Ngoài HN",IF(V37>='Trọng số'!$C$19,"Đợt 1",IF(V37>='Trọng số'!$C$20,"Đợt 2","Đợt 3"))) -> Đợt 2 | X37: =IF(K37>=4,"LMS + số hóa học liệu",IF(K37=3,"Nâng cấp/thay LMS + số hóa học liệu","Số hóa học liệu, chạy trên LMS sẵn có"))&IF(L37>=4," + mô phỏng","")&IF(M37>=4," + ngoại ngữ","") -> Nâng cấp/thay LMS + số hóa học liệu + mô phỏng | Y37: Chưa xác minh (file gốc) | Z37: C1=3: có e-learning lý thuyết | C2=5: khớp: điện–điện tử, cơ khí/ô tô/thiết bị | C3=3: ngoại ngữ là chuẩn đầu ra chung | C4=4: trường nghề nặng thực hành, học liệu chủ yếu giấy/PDF | C5=4: lớn, nhiều ngành | C6=5: Tư thục | C7=2: Không có sự kiện riêng; chỉ có động lực chính sách chung | C8=1: chưa có quan hệ (tự cập nhật) | C9=3: Vùng 3 | C10=5: đã số hóa quản lý tốt | C11=3: trường trong mạng lưới | AB37: hactech.edu.vn | AC37: File gốc #28
